Traceback (most recent call last):
  File "/Users/akirakawai/anaconda3/lib/python3.8/site-packages/jupyter_cache/executors/utils.py", line 51, in single_nb_execution
    executenb(
  File "/Users/akirakawai/anaconda3/lib/python3.8/site-packages/nbclient/client.py", line 1087, in execute
    return NotebookClient(nb=nb, resources=resources, km=km, **kwargs).execute()
  File "/Users/akirakawai/anaconda3/lib/python3.8/site-packages/nbclient/util.py", line 74, in wrapped
    return just_run(coro(*args, **kwargs))
  File "/Users/akirakawai/anaconda3/lib/python3.8/site-packages/nbclient/util.py", line 53, in just_run
    return loop.run_until_complete(coro)
  File "/Users/akirakawai/anaconda3/lib/python3.8/asyncio/base_events.py", line 616, in run_until_complete
    return future.result()
  File "/Users/akirakawai/anaconda3/lib/python3.8/site-packages/nbclient/client.py", line 540, in async_execute
    await self.async_execute_cell(
  File "/Users/akirakawai/anaconda3/lib/python3.8/site-packages/nbclient/client.py", line 832, in async_execute_cell
    self._check_raise_for_error(cell, exec_reply)
  File "/Users/akirakawai/anaconda3/lib/python3.8/site-packages/nbclient/client.py", line 740, in _check_raise_for_error
    raise CellExecutionError.from_cell_and_msg(cell, exec_reply['content'])
nbclient.exceptions.CellExecutionError: An error occurred while executing the following cell:
------------------
# Á∂ôÊâøÂÖÉ„ÅÆinit„ÅØÂëº„Å≥Âá∫„Åï„Çå„Å™„ÅÑ
student = Student('Scott', 15)
------------------

[0;31m---------------------------------------------------------------------------[0m
[0;31mTypeError[0m                                 Traceback (most recent call last)
[0;32m<ipython-input-9-2770bf25eb5c>[0m in [0;36m<module>[0;34m[0m
[1;32m      1[0m [0;31m# Á∂ôÊâøÂÖÉ„ÅÆinit„ÅØÂëº„Å≥Âá∫„Åï„Çå„Å™„ÅÑ[0m[0;34m[0m[0;34m[0m[0;34m[0m[0m
[0;32m----> 2[0;31m [0mstudent[0m [0;34m=[0m [0mStudent[0m[0;34m([0m[0;34m'Scott'[0m[0;34m,[0m [0;36m15[0m[0;34m)[0m[0;34m[0m[0;34m[0m[0m
[0m
[0;31mTypeError[0m: __init__() takes 2 positional arguments but 3 were given
TypeError: __init__() takes 2 positional arguments but 3 were given

