Traceback (most recent call last):
  File "/Users/akirakawai/Library/Python/3.8/lib/python/site-packages/jupyter_cache/executors/utils.py", line 51, in single_nb_execution
    executenb(
  File "/Library/Python/3.8/site-packages/nbclient/client.py", line 1093, in execute
    return NotebookClient(nb=nb, resources=resources, km=km, **kwargs).execute()
  File "/Library/Python/3.8/site-packages/nbclient/util.py", line 84, in wrapped
    return just_run(coro(*args, **kwargs))
  File "/Library/Python/3.8/site-packages/nbclient/util.py", line 62, in just_run
    return loop.run_until_complete(coro)
  File "/Applications/Xcode.app/Contents/Developer/Library/Frameworks/Python3.framework/Versions/3.8/lib/python3.8/asyncio/base_events.py", line 616, in run_until_complete
    return future.result()
  File "/Library/Python/3.8/site-packages/nbclient/client.py", line 559, in async_execute
    await self.async_execute_cell(
  File "/Library/Python/3.8/site-packages/nbclient/client.py", line 854, in async_execute_cell
    self._check_raise_for_error(cell, exec_reply)
  File "/Library/Python/3.8/site-packages/nbclient/client.py", line 756, in _check_raise_for_error
    raise CellExecutionError.from_cell_and_msg(cell, exec_reply_content)
nbclient.exceptions.CellExecutionError: An error occurred while executing the following cell:
------------------
x = np.linspace(0, 5, 10, endpoint=False)
y = multivariate_normal.pdf(x, mean=2.5, cov=0.5)
plt.figure()
plt.subplot(111)
plt.plot(x, y)
plt.show()ã€€
------------------

[0;36m  File [0;32m"<ipython-input-2-2ed7371bd308>"[0;36m, line [0;32m6[0m
[0;31m    plt.show()[0m
[0m              ^[0m
[0;31mSyntaxError[0m[0;31m:[0m invalid character in identifier

SyntaxError: invalid character in identifier (<ipython-input-2-2ed7371bd308>, line 6)

