Traceback (most recent call last):
  File "/Users/akirakawai/Library/Python/3.8/lib/python/site-packages/jupyter_cache/executors/utils.py", line 51, in single_nb_execution
    executenb(
  File "/Library/Python/3.8/site-packages/nbclient/client.py", line 1093, in execute
    return NotebookClient(nb=nb, resources=resources, km=km, **kwargs).execute()
  File "/Library/Python/3.8/site-packages/nbclient/util.py", line 84, in wrapped
    return just_run(coro(*args, **kwargs))
  File "/Library/Python/3.8/site-packages/nbclient/util.py", line 62, in just_run
    return loop.run_until_complete(coro)
  File "/Applications/Xcode.app/Contents/Developer/Library/Frameworks/Python3.framework/Versions/3.8/lib/python3.8/asyncio/base_events.py", line 616, in run_until_complete
    return future.result()
  File "/Library/Python/3.8/site-packages/nbclient/client.py", line 559, in async_execute
    await self.async_execute_cell(
  File "/Library/Python/3.8/site-packages/nbclient/client.py", line 854, in async_execute_cell
    self._check_raise_for_error(cell, exec_reply)
  File "/Library/Python/3.8/site-packages/nbclient/client.py", line 756, in _check_raise_for_error
    raise CellExecutionError.from_cell_and_msg(cell, exec_reply_content)
nbclient.exceptions.CellExecutionError: An error occurred while executing the following cell:
------------------
src_path = '../src/a/sample.txt'
dst_dir = '../src/b/'

shutil.move(src_path, dst_dir)
------------------

[0;31m---------------------------------------------------------------------------[0m
[0;31mFileNotFoundError[0m                         Traceback (most recent call last)
[0;32m/Applications/Xcode.app/Contents/Developer/Library/Frameworks/Python3.framework/Versions/3.8/lib/python3.8/shutil.py[0m in [0;36mmove[0;34m(src, dst, copy_function)[0m
[1;32m    790[0m     [0;32mtry[0m[0;34m:[0m[0;34m[0m[0;34m[0m[0m
[0;32m--> 791[0;31m         [0mos[0m[0;34m.[0m[0mrename[0m[0;34m([0m[0msrc[0m[0;34m,[0m [0mreal_dst[0m[0;34m)[0m[0;34m[0m[0;34m[0m[0m
[0m[1;32m    792[0m     [0;32mexcept[0m [0mOSError[0m[0;34m:[0m[0;34m[0m[0;34m[0m[0m

[0;31mFileNotFoundError[0m: [Errno 2] No such file or directory: '../src/a/sample.txt' -> '../src/b/'

During handling of the above exception, another exception occurred:

[0;31mFileNotFoundError[0m                         Traceback (most recent call last)
[0;32m<ipython-input-2-0b92c628b492>[0m in [0;36m<module>[0;34m[0m
[1;32m      2[0m [0mdst_dir[0m [0;34m=[0m [0;34m'../src/b/'[0m[0;34m[0m[0;34m[0m[0m
[1;32m      3[0m [0;34m[0m[0m
[0;32m----> 4[0;31m [0mshutil[0m[0;34m.[0m[0mmove[0m[0;34m([0m[0msrc_path[0m[0;34m,[0m [0mdst_dir[0m[0;34m)[0m[0;34m[0m[0;34m[0m[0m
[0m
[0;32m/Applications/Xcode.app/Contents/Developer/Library/Frameworks/Python3.framework/Versions/3.8/lib/python3.8/shutil.py[0m in [0;36mmove[0;34m(src, dst, copy_function)[0m
[1;32m    809[0m             [0mrmtree[0m[0;34m([0m[0msrc[0m[0;34m)[0m[0;34m[0m[0;34m[0m[0m
[1;32m    810[0m         [0;32melse[0m[0;34m:[0m[0;34m[0m[0;34m[0m[0m
[0;32m--> 811[0;31m             [0mcopy_function[0m[0;34m([0m[0msrc[0m[0;34m,[0m [0mreal_dst[0m[0;34m)[0m[0;34m[0m[0;34m[0m[0m
[0m[1;32m    812[0m             [0mos[0m[0;34m.[0m[0munlink[0m[0;34m([0m[0msrc[0m[0;34m)[0m[0;34m[0m[0;34m[0m[0m
[1;32m    813[0m     [0;32mreturn[0m [0mreal_dst[0m[0;34m[0m[0;34m[0m[0m

[0;32m/Applications/Xcode.app/Contents/Developer/Library/Frameworks/Python3.framework/Versions/3.8/lib/python3.8/shutil.py[0m in [0;36mcopy2[0;34m(src, dst, follow_symlinks)[0m
[1;32m    433[0m     [0;32mif[0m [0mos[0m[0;34m.[0m[0mpath[0m[0;34m.[0m[0misdir[0m[0;34m([0m[0mdst[0m[0;34m)[0m[0;34m:[0m[0;34m[0m[0;34m[0m[0m
[1;32m    434[0m         [0mdst[0m [0;34m=[0m [0mos[0m[0;34m.[0m[0mpath[0m[0;34m.[0m[0mjoin[0m[0;34m([0m[0mdst[0m[0;34m,[0m [0mos[0m[0;34m.[0m[0mpath[0m[0;34m.[0m[0mbasename[0m[0;34m([0m[0msrc[0m[0;34m)[0m[0;34m)[0m[0;34m[0m[0;34m[0m[0m
[0;32m--> 435[0;31m     [0mcopyfile[0m[0;34m([0m[0msrc[0m[0;34m,[0m [0mdst[0m[0;34m,[0m [0mfollow_symlinks[0m[0;34m=[0m[0mfollow_symlinks[0m[0;34m)[0m[0;34m[0m[0;34m[0m[0m
[0m[1;32m    436[0m     [0mcopystat[0m[0;34m([0m[0msrc[0m[0;34m,[0m [0mdst[0m[0;34m,[0m [0mfollow_symlinks[0m[0;34m=[0m[0mfollow_symlinks[0m[0;34m)[0m[0;34m[0m[0;34m[0m[0m
[1;32m    437[0m     [0;32mreturn[0m [0mdst[0m[0;34m[0m[0;34m[0m[0m

[0;32m/Applications/Xcode.app/Contents/Developer/Library/Frameworks/Python3.framework/Versions/3.8/lib/python3.8/shutil.py[0m in [0;36mcopyfile[0;34m(src, dst, follow_symlinks)[0m
[1;32m    262[0m         [0mos[0m[0;34m.[0m[0msymlink[0m[0;34m([0m[0mos[0m[0;34m.[0m[0mreadlink[0m[0;34m([0m[0msrc[0m[0;34m)[0m[0;34m,[0m [0mdst[0m[0;34m)[0m[0;34m[0m[0;34m[0m[0m
[1;32m    263[0m     [0;32melse[0m[0;34m:[0m[0;34m[0m[0;34m[0m[0m
[0;32m--> 264[0;31m         [0;32mwith[0m [0mopen[0m[0;34m([0m[0msrc[0m[0;34m,[0m [0;34m'rb'[0m[0;34m)[0m [0;32mas[0m [0mfsrc[0m[0;34m,[0m [0mopen[0m[0;34m([0m[0mdst[0m[0;34m,[0m [0;34m'wb'[0m[0;34m)[0m [0;32mas[0m [0mfdst[0m[0;34m:[0m[0;34m[0m[0;34m[0m[0m
[0m[1;32m    265[0m             [0;31m# macOS[0m[0;34m[0m[0;34m[0m[0;34m[0m[0m
[1;32m    266[0m             [0;32mif[0m [0m_HAS_FCOPYFILE[0m[0;34m:[0m[0;34m[0m[0;34m[0m[0m

[0;31mFileNotFoundError[0m: [Errno 2] No such file or directory: '../src/a/sample.txt'
FileNotFoundError: [Errno 2] No such file or directory: '../src/a/sample.txt'

